Workbook

Sheet Dictionary
A1: Universe | B1: filter(members('JCI Index'), BICS_LEVEL_2_INDUSTRY_GROUP_NAME == "Banking")
B3: Item | C3: Field | D3: Range | E3: Unit
A4: Data Item | B4: =CONCATENATE(C4,D4,E4) -> BS_SH_OUT(fill=prev, dates=range(start=-10y, end=0d, frq=q)).PERIOD_END_DATE | C4: BS_SH_OUT | D4: (fill=prev, dates=range(start=-10y, end=0d, frq=q)).PERIOD_END_DATE
A5: Data Item | B5: =CONCATENATE(C5,D5,E5) -> BS_TOT_ASSET(fill=prev, dates=range(start=-10y, end=0d, frq=q)).value*0.000001 | C5: BS_TOT_ASSET | D5: (fill=prev, dates=range(start=-10y, end=0d, frq=q)).value | E5: *0.000001
A6: Data Item | B6: =CONCATENATE(C6,D6,E6) -> BS_TOT_LOAN(fill=prev, dates=range(start=-10y, end=0d, frq=q)).value*0.000001 | C6: BS_TOT_LOAN | D6: (fill=prev, dates=range(start=-10y, end=0d, frq=q)).value | E6: *0.000001
A7: Data Item | B7: =CONCATENATE(C7,D7,E7) -> BS_NON_PERFORM_LOANS(fill=prev, dates=range(start=-10y, end=0d, frq=q)).value*0.000001 | C7: BS_NON_PERFORM_LOANS | D7: (fill=prev, dates=range(start=-10y, end=0d, frq=q)).value | E7: *0.000001
A8: Data Item | B8: =CONCATENATE(C8,D8,E8) -> BS_CUSTOMER_DEPOSITS(fill=prev, dates=range(start=-10y, end=0d, frq=q)).value*0.000001 | C8: BS_CUSTOMER_DEPOSITS | D8: (fill=prev, dates=range(start=-10y, end=0d, frq=q)).value | E8: *0.000001
A9: Data Item | B9: =CONCATENATE(C9,D9,E9) -> BS_RISK_WEIGHTED_ASSETS(fill=prev, dates=range(start=-10y, end=0d, frq=q)).value*0.000001 | C9: BS_RISK_WEIGHTED_ASSETS | D9: (fill=prev, dates=range(start=-10y, end=0d, frq=q)).value | E9: *0.000001
A10: Data Item | B10: =CONCATENATE(C10,D10,E10) -> BS_TIER1_CAPITAL(fill=prev, dates=range(start=-10y, end=0d, frq=q)).value*0.000001 | C10: BS_TIER1_CAPITAL | D10: (fill=prev, dates=range(start=-10y, end=0d, frq=q)).value | E10: *0.000001
A11: Data Item | B11: =CONCATENATE(C11,D11,E11) -> BS_TOT_CAP_FUND(fill=prev, dates=range(start=-10y, end=0d, frq=q)).value*0.000001 | C11: BS_TOT_CAP_FUND | D11: (fill=prev, dates=range(start=-10y, end=0d, frq=q)).value | E11: *0.000001
A12: Data Item | B12: =CONCATENATE(C12,D12,E12) -> BS_TIER1_CAP_RATIO(fill=prev, dates=range(start=-10y, end=0d, frq=q)).value | C12: BS_TIER1_CAP_RATIO | D12: (fill=prev, dates=range(start=-10y, end=0d, frq=q)).value
A13: Data Item | B13: =CONCATENATE(C13,D13,E13) -> BS_TOT_CAP_TO_RISK_BASE_CAP(fill=prev, dates=range(start=-10y, end=0d, frq=q)).value | C13: BS_TOT_CAP_TO_RISK_BASE_CAP | D13: (fill=prev, dates=range(start=-10y, end=0d, frq=q)).value
A14: Data Item | B14: =CONCATENATE(C14,D14,E14) -> IS_INT_INC(FA_PERIOD_TYPE=Q, fill=prev, dates=range(start=-10y, end=0d, frq=q)).value*0.000001 | C14: IS_INT_INC | D14: (FA_PERIOD_TYPE=Q, fill=prev, dates=range(start=-10y, end=0d, frq=q)).value | E14: *0.000001
A15: Data Item | B15: =CONCATENATE(C15,D15,E15) -> IS_PROV_FOR_LOAN_LOSS(FA_PERIOD_TYPE=Q, fill=prev, dates=range(start=-10y, end=0d, frq=q)).value*0.000001 | C15: IS_PROV_FOR_LOAN_LOSS | D15: (FA_PERIOD_TYPE=Q, fill=prev, dates=range(start=-10y, end=0d, frq=q)).value | E15: *0.000001
A16: Data Item | B16: =CONCATENATE(C16,D16,E16) -> NON_INT_INC(FA_PERIOD_TYPE=Q, fill=prev, dates=range(start=-10y, end=0d, frq=q)).value*0.000001 | C16: NON_INT_INC | D16: (FA_PERIOD_TYPE=Q, fill=prev, dates=range(start=-10y, end=0d, frq=q)).value | E16: *0.000001
A17: Data Item | B17: =CONCATENATE(C17,D17,E17) -> NON_INT_EXP(FA_PERIOD_TYPE=Q, fill=prev, dates=range(start=-10y, end=0d, frq=q)).value*0.000001 | C17: NON_INT_EXP | D17: (FA_PERIOD_TYPE=Q, fill=prev, dates=range(start=-10y, end=0d, frq=q)).value | E17: *0.000001
A18: Data Item | B18: =CONCATENATE(C18,D18,E18) -> NET_INT_INC(FA_PERIOD_TYPE=Q, fill=prev, dates=range(start=-10y, end=0d, frq=q)).value*0.000001 | C18: NET_INT_INC | D18: (FA_PERIOD_TYPE=Q, fill=prev, dates=range(start=-10y, end=0d, frq=q)).value | E18: *0.000001
A19: Data Item | B19: =CONCATENATE(C19,D19,E19) -> IS_CURRENT_INCOME_TAX_BENEFIT(FA_PERIOD_TYPE=Q, fill=prev, dates=range(start=-10y, end=0d, frq=q)).value*0.000001 | C19: IS_CURRENT_INCOME_TAX_BENEFIT | D19: (FA_PERIOD_TYPE=Q, fill=prev, dates=range(start=-10y, end=0d, frq=q)).value | E19: *0.000001
A20: Data Item | B20: =CONCATENATE(C20,D20,E20) -> IS_DEFERRED_INCOME_TAX_BENEFIT(FA_PERIOD_TYPE=Q, fill=prev, dates=range(start=-10y, end=0d, frq=q)).value*0.000001 | C20: IS_DEFERRED_INCOME_TAX_BENEFIT | D20: (FA_PERIOD_TYPE=Q, fill=prev, dates=range(start=-10y, end=0d, frq=q)).value | E20: *0.000001
A21: Data Item | B21: =CONCATENATE(C21,D21,E21) -> IS_RSRV_CHRG(FA_PERIOD_TYPE=Q, fill=prev, dates=range(start=-10y, end=0d, frq=q)).value*0.000001 | C21: IS_RSRV_CHRG | D21: (FA_PERIOD_TYPE=Q, fill=prev, dates=range(start=-10y, end=0d, frq=q)).value | E21: *0.000001
A22: Data Item | B22: =CONCATENATE(C22,D22,E22) -> NET_INCOME(FA_PERIOD_TYPE=Q, fill=prev, dates=range(start=-10y, end=0d, frq=q)).value*0.000001 | C22: NET_INCOME | D22: (FA_PERIOD_TYPE=Q, fill=prev, dates=range(start=-10y, end=0d, frq=q)).value | E22: *0.000001
A23: Data Item | B23: =CONCATENATE(C23,D23,E23) -> TRADING_SECS_FA_AT_FV_THRU_PL(FA_PERIOD_TYPE=Q, fill=prev, dates=range(start=-10y, end=0d, frq=q)).value*0.000001 | C23: TRADING_SECS_FA_AT_FV_THRU_PL | D23: (FA_PERIOD_TYPE=Q, fill=prev, dates=range(start=-10y, end=0d, frq=q)).value | E23: *0.000001
A24: Data Item | B24: =CONCATENATE(C24,D24,E24) -> AV_SA_FA_AT_FV_THRU_OT_COMP_INC(FA_PERIOD_TYPE=Q, fill=prev, dates=range(start=-10y, end=0d, frq=q)).value*0.000001 | C24: AV_SA_FA_AT_FV_THRU_OT_COMP_INC | D24: (FA_PERIOD_TYPE=Q, fill=prev, dates=range(start=-10y, end=0d, frq=q)).value | E24: *0.000001

Sheet Output Sheet
A1: {=_xll.BQL(Dictionary!B1,Dictionary!B4:B24)} -> #NAME? | W1: AV_SA_FA_AT_FV_THRU_OT_COMP_INC(fill=prev,dates=range(start=-10y,end=0d,frq=q)).value*0.000001
W2: #N/A
W3: #N/A
W4: #N/A
W5: #N/A
W6: #N/A
W7: #N/A
W8: #N/A
W9: #N/A
W10: #N/A
W11: #N/A
W12: #N/A
W13: #N/A
... W25: #N/A
W26: 80057
W27: 85061
W28: 85079
W29: 185148
W30: 185097
W31: 185096
W32: 185113
W33: 205104
W34: 205087
W35: 205056
W36: 205081
W37: 205151
... W42: 295077
W43: #N/A
W44: #N/A
W45: #N/A
W46: #N/A
W47: #N/A
W48: #N/A
W49: #N/A
W50: #N/A
W51: #N/A
W52: #N/A
W53: #N/A
W54: 30658
W55: 45424
...

Sheet Output Sheet (Copy)
A1: ID | B1: BS_SH_OUT(fill=prev,dates=range(start=-10y,end=0d,frq=q)).PERIOD_END_DATE.PERIOD_END_DATE | C1: BS_TOT_ASSET(fill=prev,dates=range(start=-10y,end=0d,frq=q)).value*0.000001 | D1: BS_TOT_LOAN(fill=prev,dates=range(start=-10y,end=0d,frq=q)).value*0.000001 | E1: BS_NON_PERFORM_LOANS(fill=prev,dates=range(start=-10y,end=0d,frq=q)).value*0.000001 | F1: BS_CUSTOMER_DEPOSITS(fill=prev,dates=range(start=-10y,end=0d,frq=q)).value*0.000001 | G1: BS_RISK_WEIGHTED_ASSETS(fill=prev,dates=range(start=-10y,end=0d,frq=q)).value*0.000001 | H1: BS_TIER1_CAPITAL(fill=prev,dates=range(start=-10y,end=0d,frq=q)).value*0.000001 | I1: BS_TOT_CAP_FUND(fill=prev,dates=range(start=-10y,end=0d,frq=q)).value*0.000001 | J1: BS_TIER1_CAP_RATIO(fill=prev,dates=range(start=-10y,end=0d,frq=q)).value | K1: BS_TOT_CAP_TO_RISK_BASE_CAP(fill=prev,dates=range(start=-10y,end=0d,frq=q)).value | L1: IS_INT_INC(FA_PERIOD_TYPE=Q,fill=prev,dates=range(start=-10y,end=0d,frq=q)).value*0.000001 | M1: IS_PROV_FOR_LOAN_LOSS(FA_PERIOD_TYPE=Q,fill=prev,dates=range(start=-10y,end=0d,frq=q)).value*0.000001 | N1: NON_INT_INC(FA_PERIOD_TYPE=Q,fill=prev,dates=range(start=-10y,end=0d,frq=q)).value*0.000001 | O1: NON_INT_EXP(FA_PERIOD_TYPE=Q,fill=prev,dates=range(start=-10y,end=0d,frq=q)).value*0.000001 | P1: NET_INT_INC(FA_PERIOD_TYPE=Q,fill=prev,dates=range(start=-10y,end=0d,frq=q)).value*0.000001 | Q1: IS_CURRENT_INCOME_TAX_BENEFIT(FA_PERIOD_TYPE=Q,fill=prev,dates=range(start=-10y,end=0d,frq=q)).value*0.000001 | R1: IS_DEFERRED_INCOME_TAX_BENEFIT(FA_PERIOD_TYPE=Q,fill=prev,dates=range(start=-10y,end=0d,frq=q)).value*0.000001 | S1: IS_RSRV_CHRG(FA_PERIOD_TYPE=Q,fill=prev,dates=range(start=-10y,end=0d,frq=q)).value*0.000001 | T1: NET_INCOME(FA_PERIOD_TYPE=Q,fill=prev,dates=range(start=-10y,end=0d,frq=q)).value*0.000001 | U1: TRADING_SECS_FA_AT_FV_THRU_PL(FA_PERIOD_TYPE=Q,fill=prev,dates=range(start=-10y,end=0d,frq=q)).value*0.000001 | V1: AV_SA_FA_AT_FV_THRU_OT_COMP_INC(FA_PERIOD_TYPE=Q,fill=prev,dates=range(start=-10y,end=0d,frq=q)).value*0.000001 | W1: AV_SA_FA_AT_FV_THRU_OT_COMP_INC(fill=prev,dates=range(start=-10y,end=0d,frq=q)).value*0.000001
A2: AGRO IJ Equity | B2: 42551 | C2: 9402340.2 | D2: 7054289.6 | E2: 142533.89 | F2: 7692455.7 | G2: 7400684.8 | H2: 1378161.9 | I2: 1453467 | J2: 18.62 | K2: 19.64 | L2: 221715.63 | M2: 40226.88 | N2: 2180.917 | O2: 42162.978 | P2: 100772.69 | Q2: #N/A | R2: #N/A | S2: #N/A | T2: 19431.682 | U2: #N/A | V2: #N/A | W2: #N/A
A3: AGRO IJ Equity | B3: 42643 | C3: 10442619 | D3: 7605568.3 | E3: 134590.73 | F3: 8317120.1 | G3: 7971313.5 | H3: 1392309.3 | I3: 1462593.8 | J3: 17.47 | K3: 18.35 | L3: 236129.09 | M3: 24464.179 | N3: 22206.282 | O3: 59177.662 | P3: 104888.71 | Q3: #N/A | R3: #N/A | S3: #N/A | T3: 35105.51 | U3: #N/A | V3: #N/A | W3: #N/A
A4: AGRO IJ Equity | B4: 42735 | C4: 11377961 | D4: 8179753.8 | E4: 127861.81 | F4: 9223778.5 | G4: 8303739.4 | H4: 1878376.8 | I4: 1966244.5 | J4: 22.62 | K4: 23.68 | L4: 262967.69 | M4: 50125.626 | N4: 16267.196 | O4: 68230.017 | P4: 126680.51 | Q4: #N/A | R4: #N/A | S4: #N/A | T4: 20894.4 | U4: #N/A | V4: #N/A | W4: #N/A
A5: AGRO IJ Equity | B5: 42825 | C5: 12120042 | D5: 8592388 | E5: 127861.81 | F5: 9949373 | G5: 8963355 | H5: 1951392 | I5: 2012384 | J5: 21.77 | K5: 22.45 | L5: 277295 | M5: 21134 | N5: 6116 | O5: 59438 | P5: 118636 | Q5: 9244 | R5: 1778 | S5: #N/A | T5: 36251 | U5: 557924 | V5: 795123 | W5: #N/A
A6: AGRO IJ Equity | B6: 42916 | C6: 12465918 | D6: 9173526 | E6: 161212.54 | F6: 10289385 | G6: 9558678 | H6: 1954437 | I6: 2045112 | J6: 20.45 | K6: 21.4 | L6: 265553.65 | M6: 48516.386 | N6: 16925.706 | O6: 52413.156 | P6: 101724.46 | Q6: #N/A | R6: #N/A | S6: #N/A | T6: 13945.014 | U6: 400963.79 | V6: 730051.62 | W6: #N/A
A7: AGRO IJ Equity | B7: 43008 | C7: 14026503 | D7: 9837643 | E7: 208329.12 | F7: 10276435 | G7: 9982320.3 | H7: 3039628 | I7: 3123543.1 | J7: 30.45 | K7: 31.29 | L7: 314849.75 | M7: 16078.371 | N7: 5821.542 | O7: 53114.561 | P7: 128351.59 | Q7: #N/A | R7: #N/A | S7: #N/A | T7: 51628.654 | U7: 98732.424 | V7: 885409.89 | W7: #N/A
A8: AGRO IJ Equity | B8: 43100 | C8: 16325247 | D8: 10981623 | E8: 175045.63 | F8: 12421933 | G8: 10735800 | H8: 3071345 | I8: 3175342 | J8: 28.61 | K8: 29.58 | L8: 328150.79 | M8: 48843.186 | N8: 19676.514 | O8: 76460.315 | P8: 154410.53 | Q8: #N/A | R8: #N/A | S8: #N/A | T8: 38670.867 | U8: 70418.244 | V8: 862395.09 | W8: #N/A
A9: AGRO IJ Equity | B9: 43190 | C9: 17787021 | D9: 12506448 | E9: 186987.53 | F9: 13863415 | G9: 12598469 | H9: 3128654 | I9: 3217188 | J9: 24.83 | K9: 25.53 | L9: 357718.36 | M9: -6387.259 | N9: 3576.723 | O9: 71466.23 | P9: 153016.2 | Q9: #N/A | R9: #N/A | S9: #N/A | T9: 67691.577 | U9: 13149.339 | V9: 1329235.2 | W9: #N/A
A10: AGRO IJ Equity | B10: 43281 | C10: 18772415 | D10: 13163247 | E10: 198672.12 | F10: 14883025 | G10: 13370651 | H10: 3131939 | I10: 3223252 | J10: 23.42 | K10: 24.11 | L10: 384868.46 | M10: 21235.438 | N10: -787.731 | O10: 67069.43 | P10: 173041.61 | Q10: #N/A | R10: #N/A | S10: #N/A | T10: 63238.609 | U10: 13185.893 | V10: 1101436.8 | W10: #N/A
A11: AGRO IJ Equity | B11: 43373 | C11: 20905826 | D11: 13661814 | E11: 178032.15 | F11: 15819989 | G11: 13815775 | H11: 4310204 | I11: 4407281 | J11: 31.2 | K11: 31.9 | L11: 397535.13 | M11: 81696.962 | N11: 10953.408 | O11: 61646.588 | P11: 170675.63 | Q11: #N/A | R11: #N/A | S11: #N/A | T11: 35644.122 | U11: 235174.76 | V11: 996485.21 | W11: #N/A
A12: AGRO IJ Equity | B12: 43465 | C12: 23313671 | D12: 15670832 | E12: 188979.28 | F12: 18064536 | G12: 15582816 | H12: 4288129 | I12: 4416739 | J12: 27.52 | K12: 28.34 | L12: 420666.48 | M12: 48417.266 | N12: 15992.033 | O12: 68825.215 | P12: 179196.14 | Q12: #N/A | R12: #N/A | S12: #N/A | T12: 37638.315 | U12: 189157.75 | V12: 1117378.1 | W12: #N/A
A13: AGRO IJ Equity | B13: 43555 | C13: 22976902 | D13: 16309071 | E13: 209905.06 | F13: 17770771 | G13: 16595682 | H13: 4398501 | I13: 4500288 | J13: 26.5 | K13: 27.13 | L13: 453794.01 | M13: 16234.296 | N13: 14327.756 | O13: 80058.556 | P13: 160242.14 | Q13: 6146.488 | R13: 15452.348 | S13: #N/A | T13: 61108.042 | U13: 233727.96 | V13: 1101162.1 | W13: #N/A
A14: AGRO IJ Equity | B14: 43646 | C14: 24818173 | D14: 17580708 | E14: 546101.4 | F14: 18906919 | G14: 17853037 | H14: 4463757 | I14: 4537239.7 | J14: 25 | K14: 25.41 | L14: 449777.45 | M14: 83340.105 | N14: 15364.605 | O14: 77807.04 | P14: 172687.34 | Q14: #N/A | R14: #N/A | S14: #N/A | T14: 17189.089 | U14: 260661.62 | V14: 1097674.4 | W14: #N/A
A15: AGRO IJ Equity | B15: 43738 | C15: 24924164 | D15: 18390023 | E15: 235931.21 | F15: 19703907 | G15: 18430139 | H15: 4385494 | I15: 4496621.7 | J15: 23.8 | K15: 24.4 | L15: 483004.26 | M15: 192249.61 | N15: 9864.495 | O15: 82090.667 | P15: 178002.85 | Q15: #N/A | R15: #N/A | S15: #N/A | T15: -63005.792 | U15: 213465.65 | V15: 1014137.1 | W15: #N/A
A16: AGRO IJ Equity | B16: 43830 | C16: 27067923 | D16: 19366245 | E16: 260470.21 | F16: 21144601 | G16: 18863096 | H16: 4431690.9 | I16: 4580127.4 | J16: 23.49 | K16: 24.28 | L16: 506881.94 | M16: 81944.063 | N16: 24533.726 | O16: 72084.23 | P16: 182278.23 | Q16: #N/A | R16: #N/A | S16: #N/A | T16: 35770.082 | U16: 1073354.1 | V16: 1332140 | W16: #N/A
A17: AGRO IJ Equity | B17: 43921 | C17: 26601258 | D17: 18914203 | E17: 1577138.8 | F17: 21009322 | G17: 18545015 | H17: 4045964 | I17: 4151652.2 | J17: 21.82 | K17: 22.39 | L17: 486401.03 | M17: 85543.756 | N17: -5174.435 | O17: 77566.05 | P17: 189497.3 | Q17: #N/A | R17: #N/A | S17: #N/A | T17: 16703.823 | U17: 52067.4 | V17: 1466513.4 | W17: #N/A
A18: AGRO IJ Equity | B18: 44012 | C18: 26183539 | D18: 19198358 | E18: 1576997.4 | F18: 21067394 | G18: 18274188 | H18: 4131908.6 | I18: 4241139.7 | J18: 22.61 | K18: 23.21 | L18: 414437.86 | M18: 57496.639 | N18: 10994.953 | O18: 81406.238 | P18: 133814.38 | Q18: #N/A | R18: #N/A | S18: #N/A | T18: 3300.238 | U18: 152176 | V18: 2038154.8 | W18: #N/A
A19: AGRO IJ Equity | B19: 44104 | C19: 27935095 | D19: 19932344 | E19: 1441535.7 | F19: 23016732 | G19: 19029376 | H19: 4173402.9 | I19: 4300043.1 | J19: 21.93 | K19: 22.6 | L19: 416521.25 | M19: 83604.237 | N19: 22589.832 | O19: 70471.751 | P19: 139927.98 | Q19: #N/A | R19: #N/A | S19: #N/A | T19: 5396.688 | U19: #N/A | V19: 2346556.9 | W19: #N/A
A20: AGRO IJ Equity | B20: 44196 | C20: 28015492 | D20: 19491934 | E20: 108944.34 | F20: 22995279 | G20: 17693804 | H20: 4164447.6 | I20: 4305030.5 | J20: 23.54 | K20: 24.33 | L20: 406354.82 | M20: 80848.98 | N20: 26558.542 | O20: 84906.01 | P20: 161395.93 | Q20: #N/A | R20: #N/A | S20: #N/A | T20: 5859.933 | U20: 551320 | V20: 2197950.6 | W20: #N/A
A21: AGRO IJ Equity | B21: 44286 | C21: 24908842 | D21: 18488594 | E21: 96963.194 | F21: 19317890 | G21: 17517209 | H21: 4092786.5 | I21: 4220970.3 | J21: 23.36 | K21: 24.1 | L21: 402330.45 | M21: 113766.97 | N21: 8541.63 | O21: 79345.277 | P21: 212531.88 | Q21: 13613.327 | R21: -1702.752 | S21: #N/A | T21: 17866.551 | U21: 988620.1 | V21: 2459860.4 | W21: #N/A
A22: AGRO IJ Equity | B22: 44377 | C22: 25403477 | D22: 18369481 | E22: 85662.087 | F22: 20054694 | G22: 17431216 | H22: 4215731.7 | I22: 4340767.4 | J22: 24.18 | K22: 24.9 | L22: 372435.13 | M22: 128928.41 | N22: 20955.459 | O22: 92838.517 | P22: 221129.81 | Q22: -5908.129 | R22: 9208.919 | S22: #N/A | T22: 8352.221 | U22: 1280268.4 | V22: 2209706.5 | W22: #N/A
A23: AGRO IJ Equity | B23: 44469 | C23: 20534581 | D23: 14320814 | E23: 36977.473 | F23: 16862850 | G23: 14213560 | H23: 2383017 | I23: 2483592 | J23: 16.77 | K23: 17.47 | L23: 358776.58 | M23: 2027147.1 | N23: 9583.296 | O23: 99933.567 | P23: 223010.66 | Q23: -7705.198 | R23: -38926.42 | S23: #N/A | T23: -1858046.9 | U23: 1674625.3 | V23: 2325643.3 | W23: #N/A
A24: AGRO IJ Equity | B24: 44561 | C24: 16866523 | D24: 11608327 | E24: 41107.516 | F24: 13496292 | G24: 10664558 | H24: 2083284.9 | I24: 2158071 | J24: 19.53 | K24: 20.24 | L24: 307113.43 | M24: 1542785.8 | N24: 23834.888 | O24: 129710.39 | P24: 216896.21 | Q24: 13521.982 | R24: -239531.67 | S24: #N/A | T24: -1213873.3 | U24: 159934 | V24: 2320510.1 | W24: #N/A
A25: AGRO IJ Equity | B25: 44651 | C25: 13193287 | D25: 9527114.8 | E25: 120717.45 | F25: 10150997 | G25: 8572933.1 | H25: 2165771.4 | I25: 2218155.9 | J25: 25.26 | K25: 25.87 | L25: 242466.22 | M25: -14511.769 | N25: 15514.984 | O25: 116919.07 | P25: 186949.21 | Q25: 0 | R25: 78285.258 | S25: #N/A | T25: 47711.324 | U25: 432052 | V25: 1874768.7 | W25: #N/A
A26: AGRO IJ Equity | B26: 44742 | C26: 14477353 | D26: 9267396.4 | E26: 551895.47 | F26: 11506445 | G26: 8445658 | H26: 2116725 | I26: 2156143 | J26: 25.06 | K26: 25.53 | L26: 207699.6 | M26: 70934.403 | N26: 17142.798 | O26: 134413.64 | P26: 170263.7 | Q26: 0 | R26: 13846.361 | S26: #N/A | T26: -32332.138 | U26: 98317 | V26: 1800771.5 | W26: 80057
A27: AGRO IJ Equity | B27: 44834 | C27: 12985038 | D27: 8374410.1 | E27: 171726.8 | F27: 9624110.5 | G27: 7750843 | H27: 2076291 | I27: 2118573 | J27: 26.79 | K27: 27.33 | L27: 183957 | M27: 10627.001 | N27: 7896.886 | O27: 155351.49 | P27: 156938.54 | Q27: 0 | R27: -15684.636 | S27: #N/A | T27: 17092.963 | U27: 263799.38 | V27: 1852679.3 | W27: 85061
A28: AGRO IJ Equity | B28: 44926 | C28: 13898775 | D28: 7766644 | E28: 225538.04 | F28: 9814901 | G28: 7263740 | H28: 3106731 | I28: 3177013 | J28: 42.77 | K28: 43.74 | L28: 185288.69 | M28: -19448.704 | N28: 12697.432 | O28: 175605.16 | P28: 146284.19 | Q28: 0 | R28: 28278.592 | S28: #N/A | T28: -21011.644 | U28: 118313.1 | V28: 2197792 | W28: 85079
A29: AGRO IJ Equity | B29: 45016 | C29: 12643164 | D29: 6866379.6 | E29: 281860.67 | F29: 8748571.1 | G29: 7899472 | H29: 3130344 | I29: 3192904 | J29: 39.63 | K29: 40.42 | L29: 166727.62 | M29: -28889.648 | N29: 22896.077 | O29: 155223.42 | P29: 123818.93 | Q29: 0 | R29: 17721.191 | S29: #N/A | T29: 4371.868 | U29: 411030.65 | V29: 2017678.4 | W29: 185148
A30: AGRO IJ Equity | B30: 45107 | C30: 12008289 | D30: 6048954.5 | E30: 263201.26 | F30: 8199912.7 | G30: 7070404 | H30: 3235798 | I30: 3294550 | J30: 45.77 | K30: 46.6 | L30: 143126.7 | M30: -131600.99 | N30: 26243.707 | O30: 161600.88 | P30: 110009.13 | Q30: 0 | R30: 99734.589 | S30: #N/A | T30: 4903.279 | U30: 489745.36 | V30: 1484396.4 | W30: 185097
A31: AGRO IJ Equity | B31: 45199 | C31: 11433447 | D31: 5622225.5 | E31: 266810.24 | F31: 7065312.9 | G31: 6655777 | H31: 3213474 | I31: 3260259 | J31: 48.28 | K31: 48.98 | L31: 150917 | M31: -5038.434 | N31: 13130.171 | O31: 129803.91 | P31: 125412.66 | Q31: 0 | R31: 8772.761 | S31: #N/A | T31: 5397.638 | U31: 750118.16 | V31: 1690964.1 | W31: 185096
A32: AGRO IJ Equity | B32: 45291 | C32: 12440642 | D32: 6893331.4 | E32: 303458.74 | F32: 8185975.6 | G32: 7434454 | H32: 3195692 | I32: 3259180 | J32: 42.98 | K32: 43.84 | L32: 160513.39 | M32: -41182.874 | N32: -12616.417 | O32: 173574.21 | P32: 128588.29 | Q32: 0 | R32: -22188.557 | S32: #N/A | T32: 9678.254 | U32: 319205 | V32: 1999727 | W32: 185113
A33: AGRO IJ Equity | B33: 45382 | C33: 12241486 | D33: 6756223.6 | E33: 288838.7 | F33: 8050248.8 | G33: 7216261.5 | H33: 3213945.1 | I33: 3270997.5 | J33: 44.54 | K33: 45.33 | L33: 182905.42 | M33: -23294.644 | N33: 10942.345 | O33: 148055.13 | P33: 134856.88 | Q33: 0 | R33: 12276.991 | S33: #N/A | T33: 9162.372 | U33: 657482.96 | V33: 2078793.5 | W33: 205104
A34: AGRO IJ Equity | B34: 45473 | C34: 13084223 | D34: 6783366.4 | E34: 280606.61 | F34: 8669095.4 | G34: 8025038.1 | H34: 3214618.9 | I34: 3277357.9 | J34: 40.06 | K34: 40.84 | L34: 182805.13 | M34: -38426.686 | N34: 9803.772 | O34: 158361.02 | P34: 139919.3 | Q34: 0 | R34: 15457.578 | S34: #N/A | T34: 10862.881 | U34: 967396.85 | V34: 2273632.9 | W34: 205087
A35: AGRO IJ Equity | B35: 45565 | C35: 12821304 | D35: 6784338.2 | E35: 246672.24 | F35: 7855475.5 | G35: 7640601 | H35: 3180499.2 | I35: 3236610 | J35: 41.63 | K35: 42.36 | L35: 183948.37 | M35: 35026.156 | N35: 10774.74 | O35: 167294.7 | P35: 141458.17 | Q35: 0 | R35: -72341.561 | S35: #N/A | T35: 13858.954 | U35: 926275.26 | V35: 2174567.7 | W35: 205056
A36: AGRO IJ Equity | B36: 45657 | C36: 13128920 | D36: 7125950.7 | E36: 229702.79 | F36: 8133052 | G36: 7392890 | H36: 3212876 | I36: 3274030 | J36: 43.46 | K36: 44.29 | L36: 197661.46 | M36: -54239.309 | N36: 5010.819 | O36: 163348.71 | P36: 155735.02 | Q36: 0 | R36: 49057.18 | S36: #N/A | T36: 17007.563 | U36: 295309.03 | V36: 2336669.5 | W36: 205081
A37: AGRO IJ Equity | B37: 45747 | C37: 13346604 | D37: 7341107.2 | E37: 271923.43 | F37: 8362876.7 | G37: 8024686 | H37: 3229967 | I37: 3293314 | J37: 40.25 | K37: 41.04 | L37: 212021.96 | M37: 18078.839 | N37: 22980.492 | O37: 146141.48 | P37: 163307.6 | Q37: 0 | R37: 6391.553 | S37: #N/A | T37: 16923.362 | U37: 769399.57 | V37: 2223915.4 | W37: 205151
... A42: AGRO IJ Equity | B42: 46203 | C42: 12925804 | D42: 6762571.4 | E42: 139190.63 | F42: 8117322.7 | G42: 7072414 | H42: 2819338 | I42: 2885055 | J42: 39.86 | K42: 40.79 | L42: 223036.68 | M42: 30862.818 | N42: 8650.851 | O42: 168052.45 | P42: 194557.51 | Q42: 0 | R42: 0 | S42: #N/A | T42: 5221.327 | U42: 642613 | V42: 2154762.7 | W42: 295077
A43: AGRS IJ Equity | B43: 42551 | C43: 4061914 | D43: 2680404 | E43: 73367 | F43: 3436180 | G43: 2981870 | H43: 534885 | I43: 565771 | J43: 17.94 | K43: 18.98 | L43: 84674 | M43: 3514 | N43: 3222 | O43: 30964 | P43: 34260 | Q43: #N/A | R43: #N/A | S43: #N/A | T43: 3004 | U43: #N/A | V43: #N/A | W43: #N/A
A44: AGRS IJ Equity | B44: 42643 | C44: 3831445 | D44: 2582751 | E44: 69408 | F44: 3208698 | G44: 2826527 | H44: 548233 | I44: 573333 | J44: 19.4 | K44: 20.28 | L44: 85487 | M44: 4439 | N44: 3431 | O44: 35120 | P44: 39232 | Q44: #N/A | R44: #N/A | S44: #N/A | T44: 3104 | U44: #N/A | V44: #N/A | W44: #N/A
...

Sheet Legend
A1: Data Item | B1: Description
A2: BS_TOT_ASSET | B2: Total assets
A3: BS_TOT_LOAN | B3: Total loans
A4: BS_NON_PERFORM_LOANS | B4: Non-performing loans
A5: BS_CUSTOMER_DEPOSITS | B5: Total deposits
A6: BS_RISK_WEIGHTED_ASSETS | B6: Risk-weighted assets
A7: BS_TIER1_CAPITAL | B7: Tier 1 capital
A8: BS_TOT_CAP_FUND | B8: Total capital funds
A9: BS_TIER1_CAP_RATIO | B9: Tier 1 capital ratio (%)
A10: BS_TOT_CAP_TO_RISK_BASE_CAP | B10: Total risk-based capital ratio (%)
A11: IS_INT_INC | B11: Interest income
A12: IS_PROV_FOR_LOAN_LOSS | B12: Provision for loan losses
... A21: AV_SA_FA_AT_FV_THRU_OT_COMP_INC | B21: Available for sales financial assets at fair value through other comprehensive income (FVOCI)

Sheet Sheet1
A1: Cek FVTPL + FVOCI vs Total Kredit & Total Aset (IDR mn)
A2: Sumber: 'Output Sheet (Copy)' baris 2–2010. Kolom FVTPL = TRADING_SECS_FA_AT_FV_THRU_PL, FVOCI = AV_SA_FA_AT_FV_THRU_OT_COMP_INC (FA_PERIOD_TYPE=Q).
A4: Ringkasan
A5: Baris dengan data FVTPL/FVOCI | B5: =COUNT(G13:G2021) -> 1545
A6: FVTPL+FVOCI > Total Kredit | B6: =COUNTIF(J13:J2021,"YA") -> 18
A7: Total Kredit = 0 / kosong (tidak bisa dicek) | B7: =COUNTIF(J13:J2021,"Kredit 0/NA") -> 2
A8: FVTPL+FVOCI > Total Aset | B8: =COUNTIF(K13:K2021,"YA") -> 0
A9: Rasio (FVTPL+FVOCI)/Aset tertinggi | B9: =MAX(I13:I2021) -> 0.61632629
A10: FVTPL+FVOCI+Kredit > Total Aset | B10: =COUNTIF(M13:M2021,"YA") -> 0
A11: Rasio (FV+Kredit)/Aset tertinggi | B11: =MAX(N13:N2021) -> 0.93564561
A12: Bank | B12: Period End | C12: Total Aset | D12: Total Kredit | E12: FVTPL | F12: FVOCI | G12: FVTPL+FVOCI | H12: % thd Kredit | I12: % thd Aset | J12: > Kredit? | K12: > Aset? | L12: FV+Kredit | M12: FV+Kredit > Aset? | N12: (FV+Kredit)/Aset
A13: ='Output Sheet (Copy)'!A2 -> AGRO IJ Equity | B13: ='Output Sheet (Copy)'!B2 -> 42551 | C13: =IFERROR('Output Sheet (Copy)'!C2,"") -> 9402340.2 | D13: =IFERROR('Output Sheet (Copy)'!D2,"") -> 7054289.6 | E13: =IFERROR('Output Sheet (Copy)'!U2,"") | F13: =IFERROR('Output Sheet (Copy)'!V2,"") | G13: =IF(AND(E13="",F13=""),"",N(E13)+N(F13)) | H13: =IF(OR(G13="",N(D13)=0),"",G13/D13) | I13: =IF(OR(G13="",N(C13)=0),"",G13/C13) | J13: =IF(G13="","",IF(N(D13)=0,"Kredit 0/NA",IF(G13>D13,"YA",""))) | K13: =IF(G13="","",IF(N(C13)=0,"Aset 0/NA",IF(G13>C13,"YA",""))) | L13: =IF(G13="","",G13+N(D13)) | M13: =IF(L13="","",IF(N(C13)=0,"Aset 0/NA",IF(L13>C13,"YA",""))) | N13: =IF(OR(L13="",N(C13)=0),"",L13/C13)
A14: ='Output Sheet (Copy)'!A3 -> AGRO IJ Equity | B14: ='Output Sheet (Copy)'!B3 -> 42643 | C14: =IFERROR('Output Sheet (Copy)'!C3,"") -> 10442619 | D14: =IFERROR('Output Sheet (Copy)'!D3,"") -> 7605568.3 | E14: =IFERROR('Output Sheet (Copy)'!U3,"") | F14: =IFERROR('Output Sheet (Copy)'!V3,"") | G14: =IF(AND(E14="",F14=""),"",N(E14)+N(F14)) | H14: =IF(OR(G14="",N(D14)=0),"",G14/D14) | I14: =IF(OR(G14="",N(C14)=0),"",G14/C14) | J14: =IF(G14="","",IF(N(D14)=0,"Kredit 0/NA",IF(G14>D14,"YA",""))) | K14: =IF(G14="","",IF(N(C14)=0,"Aset 0/NA",IF(G14>C14,"YA",""))) | L14: =IF(G14="","",G14+N(D14)) | M14: =IF(L14="","",IF(N(C14)=0,"Aset 0/NA",IF(L14>C14,"YA",""))) | N14: =IF(OR(L14="",N(C14)=0),"",L14/C14)
A15: ='Output Sheet (Copy)'!A4 -> AGRO IJ Equity | B15: ='Output Sheet (Copy)'!B4 -> 42735 | C15: =IFERROR('Output Sheet (Copy)'!C4,"") -> 11377961 | D15: =IFERROR('Output Sheet (Copy)'!D4,"") -> 8179753.8 | E15: =IFERROR('Output Sheet (Copy)'!U4,"") | F15: =IFERROR('Output Sheet (Copy)'!V4,"") | G15: =IF(AND(E15="",F15=""),"",N(E15)+N(F15)) | H15: =IF(OR(G15="",N(D15)=0),"",G15/D15) | I15: =IF(OR(G15="",N(C15)=0),"",G15/C15) | J15: =IF(G15="","",IF(N(D15)=0,"Kredit 0/NA",IF(G15>D15,"YA",""))) | K15: =IF(G15="","",IF(N(C15)=0,"Aset 0/NA",IF(G15>C15,"YA",""))) | L15: =IF(G15="","",G15+N(D15)) | M15: =IF(L15="","",IF(N(C15)=0,"Aset 0/NA",IF(L15>C15,"YA",""))) | N15: =IF(OR(L15="",N(C15)=0),"",L15/C15)
A16: ='Output Sheet (Copy)'!A5 -> AGRO IJ Equity | B16: ='Output Sheet (Copy)'!B5 -> 42825 | C16: =IFERROR('Output Sheet (Copy)'!C5,"") -> 12120042 | D16: =IFERROR('Output Sheet (Copy)'!D5,"") -> 8592388 | E16: =IFERROR('Output Sheet (Copy)'!U5,"") -> 557924 | F16: =IFERROR('Output Sheet (Copy)'!V5,"") -> 795123 | G16: =IF(AND(E16="",F16=""),"",N(E16)+N(F16)) -> 1353047 | H16: =IF(OR(G16="",N(D16)=0),"",G16/D16) -> 0.15747043 | I16: =IF(OR(G16="",N(C16)=0),"",G16/C16) -> 0.11163715 | J16: =IF(G16="","",IF(N(D16)=0,"Kredit 0/NA",IF(G16>D16,"YA",""))) | K16: =IF(G16="","",IF(N(C16)=0,"Aset 0/NA",IF(G16>C16,"YA",""))) | L16: =IF(G16="","",G16+N(D16)) -> 9945435 | M16: =IF(L16="","",IF(N(C16)=0,"Aset 0/NA",IF(L16>C16,"YA",""))) | N16: =IF(OR(L16="",N(C16)=0),"",L16/C16) -> 0.8205776
A17: ='Output Sheet (Copy)'!A6 -> AGRO IJ Equity | B17: ='Output Sheet (Copy)'!B6 -> 42916 | C17: =IFERROR('Output Sheet (Copy)'!C6,"") -> 12465918 | D17: =IFERROR('Output Sheet (Copy)'!D6,"") -> 9173526 | E17: =IFERROR('Output Sheet (Copy)'!U6,"") -> 400963.79 | F17: =IFERROR('Output Sheet (Copy)'!V6,"") -> 730051.62 | G17: =IF(AND(E17="",F17=""),"",N(E17)+N(F17)) -> 1131015.4 | H17: =IF(OR(G17="",N(D17)=0),"",G17/D17) -> 0.12329124 | I17: =IF(OR(G17="",N(C17)=0),"",G17/C17) -> 0.090728607 | J17: =IF(G17="","",IF(N(D17)=0,"Kredit 0/NA",IF(G17>D17,"YA",""))) | K17: =IF(G17="","",IF(N(C17)=0,"Aset 0/NA",IF(G17>C17,"YA",""))) | L17: =IF(G17="","",G17+N(D17)) -> 10304541 | M17: =IF(L17="","",IF(N(C17)=0,"Aset 0/NA",IF(L17>C17,"YA",""))) | N17: =IF(OR(L17="",N(C17)=0),"",L17/C17) -> 0.82661711
A18: ='Output Sheet (Copy)'!A7 -> AGRO IJ Equity | B18: ='Output Sheet (Copy)'!B7 -> 43008 | C18: =IFERROR('Output Sheet (Copy)'!C7,"") -> 14026503 | D18: =IFERROR('Output Sheet (Copy)'!D7,"") -> 9837643 | E18: =IFERROR('Output Sheet (Copy)'!U7,"") -> 98732.424 | F18: =IFERROR('Output Sheet (Copy)'!V7,"") -> 885409.89 | G18: =IF(AND(E18="",F18=""),"",N(E18)+N(F18)) -> 984142.32 | H18: =IF(OR(G18="",N(D18)=0),"",G18/D18) -> 0.10003843 | I18: =IF(OR(G18="",N(C18)=0),"",G18/C18) -> 0.070163054 | J18: =IF(G18="","",IF(N(D18)=0,"Kredit 0/NA",IF(G18>D18,"YA",""))) | K18: =IF(G18="","",IF(N(C18)=0,"Aset 0/NA",IF(G18>C18,"YA",""))) | L18: =IF(G18="","",G18+N(D18)) -> 10821785 | M18: =IF(L18="","",IF(N(C18)=0,"Aset 0/NA",IF(L18>C18,"YA",""))) | N18: =IF(OR(L18="",N(C18)=0),"",L18/C18) -> 0.7715241
A19: ='Output Sheet (Copy)'!A8 -> AGRO IJ Equity | B19: ='Output Sheet (Copy)'!B8 -> 43100 | C19: =IFERROR('Output Sheet (Copy)'!C8,"") -> 16325247 | D19: =IFERROR('Output Sheet (Copy)'!D8,"") -> 10981623 | E19: =IFERROR('Output Sheet (Copy)'!U8,"") -> 70418.244 | F19: =IFERROR('Output Sheet (Copy)'!V8,"") -> 862395.09 | G19: =IF(AND(E19="",F19=""),"",N(E19)+N(F19)) -> 932813.33 | H19: =IF(OR(G19="",N(D19)=0),"",G19/D19) -> 0.084943121 | I19: =IF(OR(G19="",N(C19)=0),"",G19/C19) -> 0.057139309 | J19: =IF(G19="","",IF(N(D19)=0,"Kredit 0/NA",IF(G19>D19,"YA",""))) | K19: =IF(G19="","",IF(N(C19)=0,"Aset 0/NA",IF(G19>C19,"YA",""))) | L19: =IF(G19="","",G19+N(D19)) -> 11914436 | M19: =IF(L19="","",IF(N(C19)=0,"Aset 0/NA",IF(L19>C19,"YA",""))) | N19: =IF(OR(L19="",N(C19)=0),"",L19/C19) -> 0.72981661
A20: ='Output Sheet (Copy)'!A9 -> AGRO IJ Equity | B20: ='Output Sheet (Copy)'!B9 -> 43190 | C20: =IFERROR('Output Sheet (Copy)'!C9,"") -> 17787021 | D20: =IFERROR('Output Sheet (Copy)'!D9,"") -> 12506448 | E20: =IFERROR('Output Sheet (Copy)'!U9,"") -> 13149.339 | F20: =IFERROR('Output Sheet (Copy)'!V9,"") -> 1329235.2 | G20: =IF(AND(E20="",F20=""),"",N(E20)+N(F20)) -> 1342384.5 | H20: =IF(OR(G20="",N(D20)=0),"",G20/D20) -> 0.10733539 | I20: =IF(OR(G20="",N(C20)=0),"",G20/C20) -> 0.075469893 | J20: =IF(G20="","",IF(N(D20)=0,"Kredit 0/NA",IF(G20>D20,"YA",""))) | K20: =IF(G20="","",IF(N(C20)=0,"Aset 0/NA",IF(G20>C20,"YA",""))) | L20: =IF(G20="","",G20+N(D20)) -> 13848833 | M20: =IF(L20="","",IF(N(C20)=0,"Aset 0/NA",IF(L20>C20,"YA",""))) | N20: =IF(OR(L20="",N(C20)=0),"",L20/C20) -> 0.77859204
A21: ='Output Sheet (Copy)'!A10 -> AGRO IJ Equity | B21: ='Output Sheet (Copy)'!B10 -> 43281 | C21: =IFERROR('Output Sheet (Copy)'!C10,"") -> 18772415 | D21: =IFERROR('Output Sheet (Copy)'!D10,"") -> 13163247 | E21: =IFERROR('Output Sheet (Copy)'!U10,"") -> 13185.893 | F21: =IFERROR('Output Sheet (Copy)'!V10,"") -> 1101436.8 | G21: =IF(AND(E21="",F21=""),"",N(E21)+N(F21)) -> 1114622.7 | H21: =IF(OR(G21="",N(D21)=0),"",G21/D21) -> 0.08467688 | I21: =IF(OR(G21="",N(C21)=0),"",G21/C21) -> 0.05937556 | J21: =IF(G21="","",IF(N(D21)=0,"Kredit 0/NA",IF(G21>D21,"YA",""))) | K21: =IF(G21="","",IF(N(C21)=0,"Aset 0/NA",IF(G21>C21,"YA",""))) | L21: =IF(G21="","",G21+N(D21)) -> 14277869 | M21: =IF(L21="","",IF(N(C21)=0,"Aset 0/NA",IF(L21>C21,"YA",""))) | N21: =IF(OR(L21="",N(C21)=0),"",L21/C21) -> 0.76057711
A22: ='Output Sheet (Copy)'!A11 -> AGRO IJ Equity | B22: ='Output Sheet (Copy)'!B11 -> 43373 | C22: =IFERROR('Output Sheet (Copy)'!C11,"") -> 20905826 | D22: =IFERROR('Output Sheet (Copy)'!D11,"") -> 13661814 | E22: =IFERROR('Output Sheet (Copy)'!U11,"") -> 235174.76 | F22: =IFERROR('Output Sheet (Copy)'!V11,"") -> 996485.21 | G22: =IF(AND(E22="",F22=""),"",N(E22)+N(F22)) -> 1231660 | H22: =IF(OR(G22="",N(D22)=0),"",G22/D22) -> 0.090153475 | I22: =IF(OR(G22="",N(C22)=0),"",G22/C22) -> 0.058914676 | J22: =IF(G22="","",IF(N(D22)=0,"Kredit 0/NA",IF(G22>D22,"YA",""))) | K22: =IF(G22="","",IF(N(C22)=0,"Aset 0/NA",IF(G22>C22,"YA",""))) | L22: =IF(G22="","",G22+N(D22)) -> 14893474 | M22: =IF(L22="","",IF(N(C22)=0,"Aset 0/NA",IF(L22>C22,"YA",""))) | N22: =IF(OR(L22="",N(C22)=0),"",L22/C22) -> 0.7124078
A23: ='Output Sheet (Copy)'!A12 -> AGRO IJ Equity | B23: ='Output Sheet (Copy)'!B12 -> 43465 | C23: =IFERROR('Output Sheet (Copy)'!C12,"") -> 23313671 | D23: =IFERROR('Output Sheet (Copy)'!D12,"") -> 15670832 | E23: =IFERROR('Output Sheet (Copy)'!U12,"") -> 189157.75 | F23: =IFERROR('Output Sheet (Copy)'!V12,"") -> 1117378.1 | G23: =IF(AND(E23="",F23=""),"",N(E23)+N(F23)) -> 1306535.9 | H23: =IF(OR(G23="",N(D23)=0),"",G23/D23) -> 0.083373738 | I23: =IF(OR(G23="",N(C23)=0),"",G23/C23) -> 0.056041618 | J23: =IF(G23="","",IF(N(D23)=0,"Kredit 0/NA",IF(G23>D23,"YA",""))) | K23: =IF(G23="","",IF(N(C23)=0,"Aset 0/NA",IF(G23>C23,"YA",""))) | L23: =IF(G23="","",G23+N(D23)) -> 16977368 | M23: =IF(L23="","",IF(N(C23)=0,"Aset 0/NA",IF(L23>C23,"YA",""))) | N23: =IF(OR(L23="",N(C23)=0),"",L23/C23) -> 0.72821514
A24: ='Output Sheet (Copy)'!A13 -> AGRO IJ Equity | B24: ='Output Sheet (Copy)'!B13 -> 43555 | C24: =IFERROR('Output Sheet (Copy)'!C13,"") -> 22976902 | D24: =IFERROR('Output Sheet (Copy)'!D13,"") -> 16309071 | E24: =IFERROR('Output Sheet (Copy)'!U13,"") -> 233727.96 | F24: =IFERROR('Output Sheet (Copy)'!V13,"") -> 1101162.1 | G24: =IF(AND(E24="",F24=""),"",N(E24)+N(F24)) -> 1334890 | H24: =IF(OR(G24="",N(D24)=0),"",G24/D24) -> 0.081849542 | I24: =IF(OR(G24="",N(C24)=0),"",G24/C24) -> 0.05809704 | J24: =IF(G24="","",IF(N(D24)=0,"Kredit 0/NA",IF(G24>D24,"YA",""))) | K24: =IF(G24="","",IF(N(C24)=0,"Aset 0/NA",IF(G24>C24,"YA",""))) | L24: =IF(G24="","",G24+N(D24)) -> 17643961 | M24: =IF(L24="","",IF(N(C24)=0,"Aset 0/NA",IF(L24>C24,"YA",""))) | N24: =IF(OR(L24="",N(C24)=0),"",L24/C24) -> 0.76789992
... A2021: ='Output Sheet (Copy)'!A2010 -> VICO IJ Equity | B2021: ='Output Sheet (Copy)'!B2010 -> 46203 | C2021: =IFERROR('Output Sheet (Copy)'!C2010,"") -> 36155014 | D2021: =IFERROR('Output Sheet (Copy)'!D2010,"") -> 22280219 | E2021: =IFERROR('Output Sheet (Copy)'!U2010,"") -> 100336.43 | F2021: =IFERROR('Output Sheet (Copy)'!V2010,"") -> 3474287 | G2021: =IF(AND(E2021="",F2021=""),"",N(E2021)+N(F2021)) -> 3574623.4 | H2021: =IF(OR(G2021="",N(D2021)=0),"",G2021/D2021) -> 0.16043933 | I2021: =IF(OR(G2021="",N(C2021)=0),"",G2021/C2021) -> 0.098869369 | J2021: =IF(G2021="","",IF(N(D2021)=0,"Kredit 0/NA",IF(G2021>D2021,"YA",""))) | K2021: =IF(G2021="","",IF(N(C2021)=0,"Aset 0/NA",IF(G2021>C2021,"YA",""))) | L2021: =IF(G2021="","",G2021+N(D2021)) -> 25854843 | M2021: =IF(L2021="","",IF(N(C2021)=0,"Aset 0/NA",IF(L2021>C2021,"YA",""))) | N2021: =IF(OR(L2021="",N(C2021)=0),"",L2021/C2021) -> 0.71511085

Sheet Sheet2
A1: Pelanggaran: FVTPL + FVOCI + Total Kredit > Total Aset (IDR mn)
A2: Daftar otomatis (FILTER) dari Sheet1 baris dengan kolom M = "YA".
A3: Jumlah pelanggaran | B3: =Sheet1!B10 -> 0
A5: =Sheet1!A12 -> Bank | B5: =Sheet1!B12 -> Period End | C5: =Sheet1!C12 -> Total Aset | D5: =Sheet1!D12 -> Total Kredit | E5: =Sheet1!E12 -> FVTPL | F5: =Sheet1!F12 -> FVOCI | G5: =Sheet1!G12 -> FVTPL+FVOCI | H5: =Sheet1!H12 -> % thd Kredit | ... N5: =Sheet1!N12 -> (FV+Kredit)/Aset
A6: {=_xlfn._xlws.FILTER(Sheet1!A13:N2021,Sheet1!M13:M2021="YA","Tidak ada pelanggaran")} -> Tidak ada pelanggaran
